Workbook
Name NativeTimeline_Order_Date: #N/A
Name Slicer_Category: #N/A
Name Slicer_Region: #N/A

Sheet Sales_Data
A1: Order_ID | B1: Customer_ID | C1: Product_ID | D1: Order_Date | E1: Delivery_Date | F1: Customer_Name | G1: Gender | H1: DOB | I1: City | J1: Region | K1: Category | L1: Product_Name | M1: Quantity | N1: Unit_Price | O1: Discount_% | P1: Sales | Q1: Rating | R1: Payment_Mode | S1: Salesperson | T1: Email | U1: Phone | V1: Order_Status
A2: ORD10001 | B2: C008 | C2: P202 | D2: 18/09/2025 | E2: 22/09/2025 | F2: Kavya Nair | G2: Female | H2: 01/08/1976 | I2: Hyderabad | J2: South | K2: Home Appliances | L2: Iron | M2: 4 | N2: 2200 | O2: 10 | P2: 7920 | Q2: 4 | R2: Cash | S2: Ritika | T2: KAvya.nair@company.com | U2: 9431429797 | V2: Completed
A3: ORD10002 | B3: C008 | C3: P104 | D3: 27/04/2025 | E3: 04/05/2025 | F3: Kavya Nair | G3: Female | H3: 16/10/2000 | I3: Delhi | J3: North | K3: Electronics | L3: Monitor | M3: 17 | N3: 12000 | O3: 10 | P3: 183600 | Q3: 1 | R3: NetBanking | S3: Rahul | T3: kavya.nair@company.com | U3: 9129865339 | V3: Completed
A4: ORD10003 | B4: C010 | C4: P101 | D4: 03/09/2025 | E4: 14/09/2025 | F4: pooja shah | G4: Female | H4: 16/09/1994 | I4: Bengaluru | J4: South | K4: Electronics | L4: Laptop | M4: 5 | N4: 55000 | O4: 5 | P4: 261250 | Q4: 3 | R4: NetBanking | S4: Aisha | T4: pooja.shah@company.com | U4: 9380975626 | V4: Pending
A5: ORD10002 | B5: C008 | C5: P202 | D5: 21/03/2026 | E5: 02/04/2026 | F5: Kavya Nair | G5: Female | H5: 07/03/2004 | I5: Bengaluru | J5: South | K5: Home Appliances | L5: Iron | M5: 5 | N5: 2200 | O5: 5 | P5: 10450 | Q5: 5 | R5: NetBanking | S5: Aisha | T5: kavya.nair@company.com | U5: 9600261125 | V5: Cancelled
A6: ORD10005 | B6: C009 | C6: P103 | D6: 27/09/2025 | E6: 07/10/2025 | F6: Mohit Verma | G6: Male | H6: 13/04/1976 | I6: Delhi | J6: North | K6: Electronics | L6: Keyboard | M6: 8 | N6: 1200 | O6: 5 | P6: 9120 | Q6: 2 | R6: Card | S6: Aisha | T6: mohit.verma@company.com | U6: 9724635978 | V6: Pending
A7: ORD10006 | B7: C007 | C7: P202 | D7: 04/01/2026 | E7: 12/01/2026 | F7: arjun Rao | G7: Male | H7: 07/02/1988 | I7: Hyderabad | J7: South | K7: Home Appliances | L7: Iron | M7: 4 | N7: 2200 | O7: 0 | P7: 8800 | Q7: 1 | R7: UPI | S7: Ritika | T7: arjun.rao@company.com | U7: 9780584905 | V7: Completed
A8: ORD10007 | B8: C008 | C8: P201 | D8: 31/02/2025 | E8: 25/02/2026 | F8: Kavya Nair | G8: Female | H8: 20/03/2003 | I8: Hyderabad | J8: South | K8: Home Appliances | L8: Mixer | M8: 2 | N8: 3500 | O8: 5 | P8: 6650 | Q8: 1 | R8: UPI | S8: Ritika | T8: kavya.nair@company.com | U8: 9958252176 | V8: Completed
A9: ORD10008 | B9: C002 | C9: P104 | D9: 13/04/2025 | E9: 19/04/2025 | F9: Priya Patel | G9: Female | H9: 07/03/1995 | I9: Mumbai | J9: West | K9: Electronics | L9: Monitor | M9: 14 | N9: 12000 | O9: 15 | P9: 142800 | Q9: 4 | R9: NetBanking | S9: Ritika | T9: priYa.patel@company.com | U9: 9705521654 | V9: Completed
A10: ORD10009 | B10: C008 | C10: P104 | D10: 31/01/2026 | E10: 02/02/2026 | F10: kavya Nair | G10: Female | H10: 06/04/1997 | I10: Pune | J10: West | K10: Electronics | L10: Monitor | M10: 4 | N10: 12000 | O10: 15 | P10: 40800 | Q10: 4 | R10: UPI | S10: Neha | T10: kavya.nair@company.com | U10: 9588041011 | V10: Completed
A11: ORD10010 | B11: C002 | C11: P301 | D11: 25/03/2025 | E11: 27/03/2025 | F11: Priya Patel | G11: Female | H11: 07/01/1990 | I11: Mumbai | J11: West | K11: Stationery | L11: Notebook | M11: 6 | N11: 60 | O11: 0 | P11: 360 | Q11: 4 | R11: Card | S11: Neha | T11: PRiya.patel@company.com | U11: 9340540608 | V11: Completed
A12: ORD10011 | B12: C003 | C12: P202 | D12: 19/09/2025 | E12: 23/09/2025 | F12: Rohit Singh | G12: Male | H12: 10/05/1982 | I12: Delhi | J12: North | K12: Home Appliances | L12: Iron | M12: -3 | N12: 2200 | O12: 0 | P12: 35200 | Q12: 2 | R12: Card | S12: Rahul | T12: rohit.singh@company.com | U12: 9521710321 | V12: Pending
A13: ORD10012 | B13: C008 | C13: P201 | D13: 08/03/2025 | E13: 15/03/2025 | F13: Kavya Nair | G13: Female | H13: 23/01/1982 | I13: Ahmedabad | J13: West | K13: Home Appliances | L13: Mixer | M13: 10 | N13: 3500 | O13: 5 | P13: 33250 | Q13: 5 | R13: Card | S13: Aisha | T13: kavya.nair@company.com | U13: 9123535241 | V13: Cancelled
... A39: ORD10038 | B39: C006 | C39: P201 | D39: 08/03/2026 | E39: 20/03/2026 | F39: Sneha Joshi | G39: Female | H39: 21/06/1980 | I39: Delhi | J39: North | K39: Home Appliances | L39: Mixer | M39: 20 | N39: 3500 | O39: 10 | P39: 63000 | Q39: 3 | R39: Card | S39: Rahul | T39: sneha.joshi@company.com | U39: 9283578533 | V39: Cancelled
A40: ORD10039 | B40: C008 | C40: P302 | D40: 13/02/2025 | E40: 19/02/2025 | F40: Kavya Nair | G40: Female | H40: 17/06/1979 | I40: Pune | J40: West | K40: Stationery | L40: Pen | M40: 5 | N40: 1200 | O40: 0 | P40: 100 | Q40: 1 | R40: Cash | S40: Rahul | T40: kavya.nair@company.com | U40: 9963005771 | V40: Cancelled
A41: ORD10040 | B41: C010 | C41: P203 | D41: 05/10/2025 | E41: 15/10/2025 | F41: Pooja Shah | G41: Female | H41: 18/06/1992 | I41: Mumbai | J41: West | K41: Home Appliances | L41: Microwave | M41: 20 | N41: 8500 | O41: 0 | P41: 170000 | Q41: 1 | R41: UPI | S41: Neha | T41: pooja.shah@company.com | U41: 9484632635 | V41: Cancelled
A42: ORD10041 | B42: C007 | C42: P301 | D42: 10/02/2026 | E42: 12/02/2026 | F42: Arjun Rao | G42: Male | H42: 06/06/1994 | I42: Bengaluru | J42: South | K42: Stationery | L42: Notebook | M42: 8 | N42: 60 | O42: 15 | P42: 408 | Q42: 5 | R42: UPI | S42: Rahul | T42: arjun.rao@company.com | U42: 9276319484 | V42: Pending
A43: ORD10042 | B43: C010 | C43: P201 | D43: 04/06/2025 | E43: 16/06/2025 | F43: Pooja Shah | G43: Female | H43: 22/09/1988 | I43: Pune | J43: West | K43: Home Appliances | L43: Mixer | M43: 8 | N43: 3500 | O43: 5 | P43: 26600 | Q43: 1 | R43: Card | S43: Neha | T43: pooja.shah@company.com | U43: 9619034852 | V43: Pending
A44: ORD10043 | B44: C009 | C44: P203 | D44: 08/02/2026 | E44: 14/02/2026 | F44: Mohit Verma | G44: Male | H44: 14/07/2001 | I44: Jaipur | J44: North | K44: Home Appliances | L44: Microwave | M44: 1 | N44: 8500 | O44: 0 | P44: 8500 | Q44: 2 | R44: Card | S44: Neha | T44: mohit.verma@company.com | U44: 9636416962 | V44: Pending
A45: ORD10044 | B45: C001 | C45: P303 | D45: 30/03/2025 | E45: 31/03/2025 | F45: amit Sharma | G45: Male | H45: 09/08/1991 | I45: Pune | J45: West | K45: Stationery | L45: Marker | M45: 8 | N45: 45 | O45: 15 | P45: 306 | Q45: 2 | R45: Card | S45: Aisha | T45: amit.sharma@company.com | U45: 9357133880 | V45: Completed
A46: ORD10045 | B46: C006 | C46: P202 | D46: 25/04/2025 | E46: 28/04/2025 | F46: Sneha Joshi | G46: Female | H46: 21/10/1988 | I46: Pune | J46: West | K46: Home Appliances | L46: Iron | M46: 16 | N46: 2200 | O46: 5 | P46: 33440 | Q46: 5 | R46: Card | S46: Aisha | T46: sneha.joshi@company.com | U46: 9575210324 | V46: Cancelled
A47: ORD10046 | B47: C009 | C47: P201 | D47: 13/10/2025 | E47: 23/10/2025 | F47: Mohit Verma | G47: Male | H47: 19/11/2002 | I47: Bengaluru | J47: South | K47: Home Appliances | L47: Mixer | M47: 19 | N47: 3500 | O47: 20 | P47: 53200 | Q47: 3 | R47: Cash | S47: Karan | T47: mohit.verma@company.com | U47: 9276080204 | V47: Cancelled
A48: ORD10047 | B48: C006 | C48: P102 | D48: 11/10/2025 | E48: 14/10/2025 | F48: Sneha Joshi | G48: Female | H48: 06/07/2000 | I48: Pune | J48: West | K48: Electronics | L48: Mouse | M48: 15 | N48: 700 | O48: 15 | P48: 8925 | Q48: 4 | R48: UPI | S48: Neha | T48: sneha.joshicompany.com | U48: 9856624471 | V48: Completed
A49: ORD10048 | B49: C006 | C49: P102 | D49: 27/11/2025 | E49: 03/12/2025 | F49: Sneha Joshi | G49: Female | H49: 26/11/1998 | I49: Jaipur | J49: North | K49: Electronics | L49: Mouse | M49: 19 | N49: 700 | O49: 20 | P49: 10640 | Q49: 1 | R49: Cash | S49: Neha | T49: sneha.joshi@company.com | U49: 9238141322 | V49: Completed
A50: ORD10049 | B50: C009 | C50: P104 | D50: 19/04/2026 | F50: Mohit Verma | G50: Male | H50: 03/06/1996 | I50: Delhi | J50: North | K50: Electronics | L50: Monitor | M50: 19 | N50: 12000 | O50: 0 | P50: 228000 | Q50: 1 | R50: NetBanking | S50: Aisha | T50: mohit.verma@company.com | U50: 9890380030 | V50: Completed
A51: ORD10050 | B51: C004 | C51: P103 | D51: 19/04/2026 | E51: 21/04/2026 | F51: Anita Gupta | G51: Female | H51: 15/03/1987 | I51: Pune | J51: West | K51: Electronics | L51: Keyboard | M51: 6 | N51: 1200 | O51: 5 | P51: 6840 | Q51: 2 | R51: Cash | S51: Ritika | T51: anita.gupta@company.com | U51: 9495893170 | V51: Pending
A52: ORD10051 | B52: C010 | C52: P202 | D52: 28/03/2025 | E52: 07/04/2025 | F52: POoja Shah | G52: Female | H52: 20/02/1979 | I52: Bengaluru | J52: South | K52: Home Appliances | L52: Iron | M52: 7 | N52: 2200 | O52: 15 | P52: 13090 | Q52: 1 | R52: UPI | S52: Aisha | T52: pooja.shah@company.com | U52: 9485166307 | V52: Completed
A53: ORD10052 | B53: C002 | C53: P301 | D53: 25/08/2025 | E53: 28/08/2025 | F53: Priya Patel | G53: Female | H53: 09/08/2000 | I53: Jaipur | J53: North | K53: Stationery | L53: Notebook | M53: 8 | N53: 60 | O53: 10 | P53: 432 | Q53: 5 | R53: Card | S53: Aisha | T53: priya.patel@company.com | U53: 9924709648 | V53: Cancelled
A54: ORD10053 | B54: C005 | C54: P101 | D54: 19/08/2025 | E54: 23/08/2025 | F54: Vikas Mehta | G54: Male | H54: 17/01/1976 | I54: Kolkata | J54: East | K54: Electronics | L54: Laptop | M54: 12 | N54: 55000 | O54: 5 | P54: 627000 | Q54: 2 | R54: UPI | S54: Rahul | T54: vikas.mehta@company.com | U54: 9350554626 | V54: Pending
A55: ORD10054 | B55: C008 | C55: P102 | D55: 27/07/2025 | E55: 05/08/2025 | F55: Kavya Nair | G55: Female | H55: 04/04/1975 | I55: Jaipur | J55: North | K55: Electronics | L55: Mouse | M55: 3 | N55: 700 | O55: 0 | P55: 2100 | Q55: 3 | R55: Card | S55: Karan | T55: kavya.nair@company.com | U55: 9743295580 | V55: Cancelled
A56: ORD10055 | B56: C003 | C56: P301 | D56: 21/02/2025 | E56: 26/02/2025 | F56: RoHit Singh | G56: Male | H56: 11/12/1976 | I56: Ahmedabad | J56: West | K56: Stationery | L56: Notebook | M56: 19 | N56: 60 | O56: 15 | P56: 969 | Q56: 4 | R56: Card | S56: Rahul | T56: rohit.singh@company.com | U56: 9822926495 | V56: Cancelled
A57: ORD10056 | B57: C001 | C57: P301 | D57: 10/08/2025 | E57: 11/08/2025 | F57: Amit Sharma | G57: Male | H57: 03/12/1979 | I57: Jaipur | J57: North | K57: Stationery | L57: Notebook | M57: 9 | N57: 60 | O57: 20 | P57: 432 | Q57: 1 | R57: NetBanking | S57: Neha | T57: amit.sharma@company.com | U57: 9518298190 | V57: Pending
A58: ORD10057 | B58: C001 | C58: P102 | D58: 24/03/2026 | E58: 30/03/2026 | F58: Amit Sharma | G58: Male | H58: 27/12/1978 | I58: Bengaluru | J58: South | K58: Electronics | L58: Mouse | M58: 6 | N58: 700 | O58: 0 | P58: 4200 | Q58: 4 | R58: UPI | S58: Rahul | T58: amit.sharmcompany.com | U58: 9366223547 | V58: Cancelled
A59: ORD10058 | B59: C003 | C59: P303 | D59: 13/03/2026 | E59: 19/03/2026 | F59: Rohit Singh | G59: Male | H59: 15/04/1975 | I59: Delhi | J59: North | K59: Stationery | L59: Marker | M59: 18 | N59: 45 | O59: 5 | P59: 769.5 | Q59: 1 | R59: Card | S59: Aisha | T59: rohit.singh@company.com | U59: 9701988524 | V59: Pending
A60: ORD10059 | B60: C007 | C60: P302 | D60: 15/06/2025 | E60: 26/06/2025 | F60: Arjun Rao | G60: Male | H60: 19/12/1988 | I60: Jaipur | J60: North | K60: Stationery | L60: Pen | M60: 8 | N60: 20 | O60: 5 | P60: 152 | Q60: 1 | R60: Card | S60: Ritika | T60: arjun.rao@company.com | U60: 9836327649 | V60: completed
A61: ORD10060 | B61: C005 | C61: P102 | D61: 05/03/2025 | E61: 06/03/2025 | F61: Vikas Mehta | G61: Male | H61: 07/03/1979 | I61: Jaipur | J61: North | K61: Electronics | L61: Mouse | M61: 8 | N61: 700 | O61: 10 | P61: 5040 | Q61: 1 | R61: NetBanking | S61: Aisha | T61: Vikas.mehta@company.com | U61: 9261800516 | V61: Cancelled
A62: ORD10061 | B62: C008 | C62: P302 | D62: 09/04/2026 | E62: 19/04/2026 | F62: Kavya Nair | G62: Female | H62: 17/12/2003 | I62: Delhi | J62: North | K62: Stationery | L62: Pen | M62: 7 | N62: 20 | O62: 15 | P62: 119 | Q62: 5 | R62: Card | S62: Rahul | T62: kavya.nair@company.com | U62: 9950802015 | V62: Completed
... A74: ORD10073 | B74: C008 | C74: P103 | D74: 13/12/2025 | E74: 23/12/2025 | F74: Kavya Nair | G74: Female | H74: 22/09/1981 | I74: Jaipur | J74: North | K74: Electronics | L74: Keyboard | M74: 1 | N74: 1200 | O74: 5 | P74: 1140 | Q74: 3 | R74: UPI | S74: Aisha | T74: kavya.nair@company.com | U74: 9808988530 | V74: Cancelled
A75: ORD10074 | B75: C010 | C75: P202 | D75: 04/02/2026 | E75: 16/02/2026 | F75: Pooja Shah | G75: Female | H75: 20/06/1980 | J75: South | K75: Home Appliances | L75: Iron | M75: 1 | N75: 2200 | O75: 15 | P75: 1870 | Q75: 4 | R75: Card | S75: Aisha | T75: pooja.shah@company.com | U75: 9286410494 | V75: Completed
A76: ORD10075 | B76: C003 | C76: P103 | D76: 26/01/2026 | E76: 28/01/2026 | F76: Rohit Singh | G76: Male | H76: 02/11/1982 | I76: Pune | J76: West | K76: Electronics | L76: Keyboard | M76: 3 | N76: 1200 | O76: 10 | P76: 3240 | Q76: 5 | R76: Cash | S76: Rahul | T76: rohit.singh@company.com | U76: 9311555196 | V76: Completed
...

Sheet Product_master
A1: Product_ID | B1: Product_Name | C1: Category | D1: Supplier | E1: Cost_Price | F1: Warranty_Months
A2: P101 | B2: Laptop | C2: Electronics | D2: TechHub | E2: 41250 | F2: 12
A3: P102 | B3: Mouse | C3: Electronics | D3: TechHub | E3: 525 | F3: 24
A4: P103 | B4: Keyboard | C4: Electronics | D4: TechHub | E4: 900 | F4: 6
A5: P104 | B5: Monitor | C5: Electronics | D5: Global Trade | E5: 9000 | F5: 24
A6: P201 | B6: Mixer | C6: Home Appliances | D6: Global Trade | E6: 2625 | F6: 6
A7: P202 | B7: Iron | C7: Home Appliances | D7: Global Trade | E7: 1650 | F7: 24
A8: P203 | B8: Microwave | C8: Home Appliances | D8: TechHub | E8: 6375 | F8: 24
A9: P301 | B9: Notebook | C9: Stationery | D9: ABC Corp | E9: 45 | F9: 12
A10: P302 | B10: Pen | C10: Stationery | D10: Prime Supplies | E10: 15 | F10: 12
A11: P303 | B11: Marker | C11: Stationery | D11: TechHub | E11: 33.75 | F11: 12

Sheet Customer_master
A1: Customer_ID | B1: Customer_Name | C1: Membership | D1: State
A2: C001 | B2: Amit Sharma | C2: Silver | D2: RJ
A3: C002 | B3: Priya Patel | C3: Platinum | D3: WB
A4: C003 | B4: Rohit Singh | C4: Gold | D4: DL
A5: C004 | B5: Anita Gupta | C5: Gold | D5: WB
A6: C005 | B6: Vikas Mehta | C6: Gold | D6: DL
A7: C006 | B7: Sneha Joshi | C7: Gold | D7: WB
A8: C007 | B8: Arjun Rao | C8: Silver | D8: RJ
A9: C008 | B9: Kavya Nair | C9: Silver | D9: WB
A10: C009 | B10: Mohit Verma | C10: Platinum | D10: KA
A11: C010 | B11: Pooja Shah | C11: Silver | D11: WB

Sheet Q1
A1: Order_ID | B1: Customer_ID | C1: Product_ID | D1: Order_Date | E1: Delivery_Date | F1: Customer_Name | G1: Gender | H1: DOB | I1: City | J1: Region | K1: Category | L1: Product_Name | M1: Quantity | N1: Unit_Price | O1: Discount_% | P1: Sales | Q1: Rating | R1: Payment_Mode | S1: Salesperson | T1: Email | U1: Phone | V1: Order_Status | W1: Customer Classification
A2: ORD10001 | B2: C008 | C2: P202 | D2: 18/09/2025 | E2: 22/09/2025 | F2: Kavya Nair | G2: Female | H2: 01/08/1976 | I2: Hyderabad | J2: South | K2: Home Appliances | L2: Iron | M2: 4 | N2: 2200 | O2: 10 | P2: 7920 | Q2: 4 | R2: Cash | S2: Ritika | T2: KAvya.nair@company.com | U2: 9431429797 | V2: Completed | W2: =IF(OR(Q2<=2, V2="Cancelled"), "Blacklisted", IF(AND(P2>=100000, Q2>=4, O2<=10, V2="Completed"), "Platinum", IF(AND(P2>=50000, P2<=99999, Q2>=3, V2="Completed"), "Gold", IF(AND(P2<50000, V2="Completed"), "Silver", "Pending")))) -> Silver
A3: ORD10002 | B3: C008 | C3: P104 | D3: 27/04/2025 | E3: 04/05/2025 | F3: Kavya Nair | G3: Female | H3: 16/10/2000 | I3: Delhi | J3: North | K3: Electronics | L3: Monitor | M3: 17 | N3: 12000 | O3: 10 | P3: 183600 | Q3: 1 | R3: NetBanking | S3: Rahul | T3: kavya.nair@company.com | U3: 9129865339 | V3: Completed | W3: =IF(OR(Q3<=2, V3="Cancelled"), "Blacklisted", IF(AND(P3>=100000, Q3>=4, O3<=10, V3="Completed"), "Platinum", IF(AND(P3>=50000, P3<=99999, Q3>=3, V3="Completed"), "Gold", IF(AND(P3<50000, V3="Completed"), "Silver", "Pending")))) -> Blacklisted
A4: ORD10003 | B4: C010 | C4: P101 | D4: 03/09/2025 | E4: 14/09/2025 | F4: pooja shah | G4: Female | H4: 16/09/1994 | I4: Bengaluru | J4: South | K4: Electronics | L4: Laptop | M4: 5 | N4: 55000 | O4: 5 | P4: 261250 | Q4: 3 | R4: NetBanking | S4: Aisha | T4: pooja.shah@company.com | U4: 9380975626 | V4: Pending | W4: =IF(OR(Q4<=2, V4="Cancelled"), "Blacklisted", IF(AND(P4>=100000, Q4>=4, O4<=10, V4="Completed"), "Platinum", IF(AND(P4>=50000, P4<=99999, Q4>=3, V4="Completed"), "Gold", IF(AND(P4<50000, V4="Completed"), "Silver", "Pending")))) -> Pending
A5: ORD10002 | B5: C008 | C5: P202 | D5: 21/03/2026 | E5: 02/04/2026 | F5: Kavya Nair | G5: Female | H5: 07/03/2004 | I5: Bengaluru | J5: South | K5: Home Appliances | L5: Iron | M5: 5 | N5: 2200 | O5: 5 | P5: 10450 | Q5: 5 | R5: NetBanking | S5: Aisha | T5: kavya.nair@company.com | U5: 9600261125 | V5: Cancelled | W5: =IF(OR(Q5<=2, V5="Cancelled"), "Blacklisted", IF(AND(P5>=100000, Q5>=4, O5<=10, V5="Completed"), "Platinum", IF(AND(P5>=50000, P5<=99999, Q5>=3, V5="Completed"), "Gold", IF(AND(P5<50000, V5="Completed"), "Silver", "Pending")))) -> Blacklisted
A6: ORD10005 | B6: C009 | C6: P103 | D6: 27/09/2025 | E6: 07/10/2025 | F6: Mohit Verma | G6: Male | H6: 13/04/1976 | I6: Delhi | J6: North | K6: Electronics | L6: Keyboard | M6: 8 | N6: 1200 | O6: 5 | P6: 9120 | Q6: 2 | R6: Card | S6: Aisha | T6: mohit.verma@company.com | U6: 9724635978 | V6: Pending | W6: =IF(OR(Q6<=2, V6="Cancelled"), "Blacklisted", IF(AND(P6>=100000, Q6>=4, O6<=10, V6="Completed"), "Platinum", IF(AND(P6>=50000, P6<=99999, Q6>=3, V6="Completed"), "Gold", IF(AND(P6<50000, V6="Completed"), "Silver", "Pending")))) -> Blacklisted
A7: ORD10006 | B7: C007 | C7: P202 | D7: 04/01/2026 | E7: 12/01/2026 | F7: arjun Rao | G7: Male | H7: 07/02/1988 | I7: Hyderabad | J7: South | K7: Home Appliances | L7: Iron | M7: 4 | N7: 2200 | O7: 0 | P7: 8800 | Q7: 1 | R7: UPI | S7: Ritika | T7: arjun.rao@company.com | U7: 9780584905 | V7: Completed | W7: =IF(OR(Q7<=2, V7="Cancelled"), "Blacklisted", IF(AND(P7>=100000, Q7>=4, O7<=10, V7="Completed"), "Platinum", IF(AND(P7>=50000, P7<=99999, Q7>=3, V7="Completed"), "Gold", IF(AND(P7<50000, V7="Completed"), "Silver", "Pending")))) -> Blacklisted
A8: ORD10007 | B8: C008 | C8: P201 | D8: 31/02/2025 | E8: 25/02/2026 | F8: Kavya Nair | G8: Female | H8: 20/03/2003 | I8: Hyderabad | J8: South | K8: Home Appliances | L8: Mixer | M8: 2 | N8: 3500 | O8: 5 | P8: 6650 | Q8: 1 | R8: UPI | S8: Ritika | T8: kavya.nair@company.com | U8: 9958252176 | V8: Completed | W8: =IF(OR(Q8<=2, V8="Cancelled"), "Blacklisted", IF(AND(P8>=100000, Q8>=4, O8<=10, V8="Completed"), "Platinum", IF(AND(P8>=50000, P8<=99999, Q8>=3, V8="Completed"), "Gold", IF(AND(P8<50000, V8="Completed"), "Silver", "Pending")))) -> Blacklisted
A9: ORD10008 | B9: C002 | C9: P104 | D9: 13/04/2025 | E9: 19/04/2025 | F9: Priya Patel | G9: Female | H9: 07/03/1995 | I9: Mumbai | J9: West | K9: Electronics | L9: Monitor | M9: 14 | N9: 12000 | O9: 15 | P9: 142800 | Q9: 4 | R9: NetBanking | S9: Ritika | T9: priYa.patel@company.com | U9: 9705521654 | V9: Completed | W9: =IF(OR(Q9<=2, V9="Cancelled"), "Blacklisted", IF(AND(P9>=100000, Q9>=4, O9<=10, V9="Completed"), "Platinum", IF(AND(P9>=50000, P9<=99999, Q9>=3, V9="Completed"), "Gold", IF(AND(P9<50000, V9="Completed"), "Silver", "Pending")))) -> Pending
A10: ORD10009 | B10: C008 | C10: P104 | D10: 31/01/2026 | E10: 02/02/2026 | F10: kavya Nair | G10: Female | H10: 06/04/1997 | I10: Pune | J10: West | K10: Electronics | L10: Monitor | M10: 4 | N10: 12000 | O10: 15 | P10: 40800 | Q10: 4 | R10: UPI | S10: Neha | T10: kavya.nair@company.com | U10: 9588041011 | V10: Completed | W10: =IF(OR(Q10<=2, V10="Cancelled"), "Blacklisted", IF(AND(P10>=100000, Q10>=4, O10<=10, V10="Completed"), "Platinum", IF(AND(P10>=50000, P10<=99999, Q10>=3, V10="Completed"), "Gold", IF(AND(P10<50000, V10="Completed"), "Silver", "Pending")))) -> Silver
A11: ORD10010 | B11: C002 | C11: P301 | D11: 25/03/2025 | E11: 27/03/2025 | F11: Priya Patel | G11: Female | H11: 07/01/1990 | I11: Mumbai | J11: West | K11: Stationery | L11: Notebook | M11: 6 | N11: 60 | O11: 0 | P11: 360 | Q11: 4 | R11: Card | S11: Neha | T11: PRiya.patel@company.com | U11: 9340540608 | V11: Completed | W11: =IF(OR(Q11<=2, V11="Cancelled"), "Blacklisted", IF(AND(P11>=100000, Q11>=4, O11<=10, V11="Completed"), "Platinum", IF(AND(P11>=50000, P11<=99999, Q11>=3, V11="Completed"), "Gold", IF(AND(P11<50000, V11="Completed"), "Silver", "Pending")))) -> Silver
A12: ORD10011 | B12: C003 | C12: P202 | D12: 19/09/2025 | E12: 23/09/2025 | F12: Rohit Singh | G12: Male | H12: 10/05/1982 | I12: Delhi | J12: North | K12: Home Appliances | L12: Iron | M12: -3 | N12: 2200 | O12: 0 | P12: 35200 | Q12: 2 | R12: Card | S12: Rahul | T12: rohit.singh@company.com | U12: 9521710321 | V12: Pending | W12: =IF(OR(Q12<=2, V12="Cancelled"), "Blacklisted", IF(AND(P12>=100000, Q12>=4, O12<=10, V12="Completed"), "Platinum", IF(AND(P12>=50000, P12<=99999, Q12>=3, V12="Completed"), "Gold", IF(AND(P12<50000, V12="Completed"), "Silver", "Pending")))) -> Blacklisted
A13: ORD10012 | B13: C008 | C13: P201 | D13: 08/03/2025 | E13: 15/03/2025 | F13: Kavya Nair | G13: Female | H13: 23/01/1982 | I13: Ahmedabad | J13: West | K13: Home Appliances | L13: Mixer | M13: 10 | N13: 3500 | O13: 5 | P13: 33250 | Q13: 5 | R13: Card | S13: Aisha | T13: kavya.nair@company.com | U13: 9123535241 | V13: Cancelled | W13: =IF(OR(Q13<=2, V13="Cancelled"), "Blacklisted", IF(AND(P13>=100000, Q13>=4, O13<=10, V13="Completed"), "Platinum", IF(AND(P13>=50000, P13<=99999, Q13>=3, V13="Completed"), "Gold", IF(AND(P13<50000, V13="Completed"), "Silver", "Pending")))) -> Blacklisted
... A39: ORD10038 | B39: C006 | C39: P201 | D39: 08/03/2026 | E39: 20/03/2026 | F39: Sneha Joshi | G39: Female | H39: 21/06/1980 | I39: Delhi | J39: North | K39: Home Appliances | L39: Mixer | M39: 20 | N39: 3500 | O39: 10 | P39: 63000 | Q39: 3 | R39: Card | S39: Rahul | T39: sneha.joshi@company.com | U39: 9283578533 | V39: Cancelled | W39: =IF(OR(Q39<=2, V39="Cancelled"), "Blacklisted", IF(AND(P39>=100000, Q39>=4, O39<=10, V39="Completed"), "Platinum", IF(AND(P39>=50000, P39<=99999, Q39>=3, V39="Completed"), "Gold", IF(AND(P39<50000, V39="Completed"), "Silver", "Pending")))) -> Blacklisted
A40: ORD10039 | B40: C008 | C40: P302 | D40: 13/02/2025 | E40: 19/02/2025 | F40: Kavya Nair | G40: Female | H40: 17/06/1979 | I40: Pune | J40: West | K40: Stationery | L40: Pen | M40: 5 | N40: 1200 | O40: 0 | P40: 100 | Q40: 1 | R40: Cash | S40: Rahul | T40: kavya.nair@company.com | U40: 9963005771 | V40: Cancelled | W40: =IF(OR(Q40<=2, V40="Cancelled"), "Blacklisted", IF(AND(P40>=100000, Q40>=4, O40<=10, V40="Completed"), "Platinum", IF(AND(P40>=50000, P40<=99999, Q40>=3, V40="Completed"), "Gold", IF(AND(P40<50000, V40="Completed"), "Silver", "Pending")))) -> Blacklisted
A41: ORD10040 | B41: C010 | C41: P203 | D41: 05/10/2025 | E41: 15/10/2025 | F41: Pooja Shah | G41: Female | H41: 18/06/1992 | I41: Mumbai | J41: West | K41: Home Appliances | L41: Microwave | M41: 20 | N41: 8500 | O41: 0 | P41: 170000 | Q41: 1 | R41: UPI | S41: Neha | T41: pooja.shah@company.com | U41: 9484632635 | V41: Cancelled | W41: =IF(OR(Q41<=2, V41="Cancelled"), "Blacklisted", IF(AND(P41>=100000, Q41>=4, O41<=10, V41="Completed"), "Platinum", IF(AND(P41>=50000, P41<=99999, Q41>=3, V41="Completed"), "Gold", IF(AND(P41<50000, V41="Completed"), "Silver", "Pending")))) -> Blacklisted
A42: ORD10041 | B42: C007 | C42: P301 | D42: 10/02/2026 | E42: 12/02/2026 | F42: Arjun Rao | G42: Male | H42: 06/06/1994 | I42: Bengaluru | J42: South | K42: Stationery | L42: Notebook | M42: 8 | N42: 60 | O42: 15 | P42: 408 | Q42: 5 | R42: UPI | S42: Rahul | T42: arjun.rao@company.com | U42: 9276319484 | V42: Pending | W42: =IF(OR(Q42<=2, V42="Cancelled"), "Blacklisted", IF(AND(P42>=100000, Q42>=4, O42<=10, V42="Completed"), "Platinum", IF(AND(P42>=50000, P42<=99999, Q42>=3, V42="Completed"), "Gold", IF(AND(P42<50000, V42="Completed"), "Silver", "Pending")))) -> Pending
A43: ORD10042 | B43: C010 | C43: P201 | D43: 04/06/2025 | E43: 16/06/2025 | F43: Pooja Shah | G43: Female | H43: 22/09/1988 | I43: Pune | J43: West | K43: Home Appliances | L43: Mixer | M43: 8 | N43: 3500 | O43: 5 | P43: 26600 | Q43: 1 | R43: Card | S43: Neha | T43: pooja.shah@company.com | U43: 9619034852 | V43: Pending | W43: =IF(OR(Q43<=2, V43="Cancelled"), "Blacklisted", IF(AND(P43>=100000, Q43>=4, O43<=10, V43="Completed"), "Platinum", IF(AND(P43>=50000, P43<=99999, Q43>=3, V43="Completed"), "Gold", IF(AND(P43<50000, V43="Completed"), "Silver", "Pending")))) -> Blacklisted
A44: ORD10043 | B44: C009 | C44: P203 | D44: 08/02/2026 | E44: 14/02/2026 | F44: Mohit Verma | G44: Male | H44: 14/07/2001 | I44: Jaipur | J44: North | K44: Home Appliances | L44: Microwave | M44: 1 | N44: 8500 | O44: 0 | P44: 8500 | Q44: 2 | R44: Card | S44: Neha | T44: mohit.verma@company.com | U44: 9636416962 | V44: Pending | W44: =IF(OR(Q44<=2, V44="Cancelled"), "Blacklisted", IF(AND(P44>=100000, Q44>=4, O44<=10, V44="Completed"), "Platinum", IF(AND(P44>=50000, P44<=99999, Q44>=3, V44="Completed"), "Gold", IF(AND(P44<50000, V44="Completed"), "Silver", "Pending")))) -> Blacklisted
A45: ORD10044 | B45: C001 | C45: P303 | D45: 30/03/2025 | E45: 31/03/2025 | F45: amit Sharma | G45: Male | H45: 09/08/1991 | I45: Pune | J45: West | K45: Stationery | L45: Marker | M45: 8 | N45: 45 | O45: 15 | P45: 306 | Q45: 2 | R45: Card | S45: Aisha | T45: amit.sharma@company.com | U45: 9357133880 | V45: Completed | W45: =IF(OR(Q45<=2, V45="Cancelled"), "Blacklisted", IF(AND(P45>=100000, Q45>=4, O45<=10, V45="Completed"), "Platinum", IF(AND(P45>=50000, P45<=99999, Q45>=3, V45="Completed"), "Gold", IF(AND(P45<50000, V45="Completed"), "Silver", "Pending")))) -> Blacklisted
A46: ORD10045 | B46: C006 | C46: P202 | D46: 25/04/2025 | E46: 28/04/2025 | F46: Sneha Joshi | G46: Female | H46: 21/10/1988 | I46: Pune | J46: West | K46: Home Appliances | L46: Iron | M46: 16 | N46: 2200 | O46: 5 | P46: 33440 | Q46: 5 | R46: Card | S46: Aisha | T46: sneha.joshi@company.com | U46: 9575210324 | V46: Cancelled | W46: =IF(OR(Q46<=2, V46="Cancelled"), "Blacklisted", IF(AND(P46>=100000, Q46>=4, O46<=10, V46="Completed"), "Platinum", IF(AND(P46>=50000, P46<=99999, Q46>=3, V46="Completed"), "Gold", IF(AND(P46<50000, V46="Completed"), "Silver", "Pending")))) -> Blacklisted
A47: ORD10046 | B47: C009 | C47: P201 | D47: 13/10/2025 | E47: 23/10/2025 | F47: Mohit Verma | G47: Male | H47: 19/11/2002 | I47: Bengaluru | J47: South | K47: Home Appliances | L47: Mixer | M47: 19 | N47: 3500 | O47: 20 | P47: 53200 | Q47: 3 | R47: Cash | S47: Karan | T47: mohit.verma@company.com | U47: 9276080204 | V47: Cancelled | W47: =IF(OR(Q47<=2, V47="Cancelled"), "Blacklisted", IF(AND(P47>=100000, Q47>=4, O47<=10, V47="Completed"), "Platinum", IF(AND(P47>=50000, P47<=99999, Q47>=3, V47="Completed"), "Gold", IF(AND(P47<50000, V47="Completed"), "Silver", "Pending")))) -> Blacklisted
A48: ORD10047 | B48: C006 | C48: P102 | D48: 11/10/2025 | E48: 14/10/2025 | F48: Sneha Joshi | G48: Female | H48: 06/07/2000 | I48: Pune | J48: West | K48: Electronics | L48: Mouse | M48: 15 | N48: 700 | O48: 15 | P48: 8925 | Q48: 4 | R48: UPI | S48: Neha | T48: sneha.joshicompany.com | U48: 9856624471 | V48: Completed | W48: =IF(OR(Q48<=2, V48="Cancelled"), "Blacklisted", IF(AND(P48>=100000, Q48>=4, O48<=10, V48="Completed"), "Platinum", IF(AND(P48>=50000, P48<=99999, Q48>=3, V48="Completed"), "Gold", IF(AND(P48<50000, V48="Completed"), "Silver", "Pending")))) -> Silver
A49: ORD10048 | B49: C006 | C49: P102 | D49: 27/11/2025 | E49: 03/12/2025 | F49: Sneha Joshi | G49: Female | H49: 26/11/1998 | I49: Jaipur | J49: North | K49: Electronics | L49: Mouse | M49: 19 | N49: 700 | O49: 20 | P49: 10640 | Q49: 1 | R49: Cash | S49: Neha | T49: sneha.joshi@company.com | U49: 9238141322 | V49: Completed | W49: =IF(OR(Q49<=2, V49="Cancelled"), "Blacklisted", IF(AND(P49>=100000, Q49>=4, O49<=10, V49="Completed"), "Platinum", IF(AND(P49>=50000, P49<=99999, Q49>=3, V49="Completed"), "Gold", IF(AND(P49<50000, V49="Completed"), "Silver", "Pending")))) -> Blacklisted
A50: ORD10049 | B50: C009 | C50: P104 | D50: 19/04/2026 | F50: Mohit Verma | G50: Male | H50: 03/06/1996 | I50: Delhi | J50: North | K50: Electronics | L50: Monitor | M50: 19 | N50: 12000 | O50: 0 | P50: 228000 | Q50: 1 | R50: NetBanking | S50: Aisha | T50: mohit.verma@company.com | U50: 9890380030 | V50: Completed | W50: =IF(OR(Q50<=2, V50="Cancelled"), "Blacklisted", IF(AND(P50>=100000, Q50>=4, O50<=10, V50="Completed"), "Platinum", IF(AND(P50>=50000, P50<=99999, Q50>=3, V50="Completed"), "Gold", IF(AND(P50<50000, V50="Completed"), "Silver", "Pending")))) -> Blacklisted
A51: ORD10050 | B51: C004 | C51: P103 | D51: 19/04/2026 | E51: 21/04/2026 | F51: Anita Gupta | G51: Female | H51: 15/03/1987 | I51: Pune | J51: West | K51: Electronics | L51: Keyboard | M51: 6 | N51: 1200 | O51: 5 | P51: 6840 | Q51: 2 | R51: Cash | S51: Ritika | T51: anita.gupta@company.com | U51: 9495893170 | V51: Pending | W51: =IF(OR(Q51<=2, V51="Cancelled"), "Blacklisted", IF(AND(P51>=100000, Q51>=4, O51<=10, V51="Completed"), "Platinum", IF(AND(P51>=50000, P51<=99999, Q51>=3, V51="Completed"), "Gold", IF(AND(P51<50000, V51="Completed"), "Silver", "Pending")))) -> Blacklisted
A52: ORD10051 | B52: C010 | C52: P202 | D52: 28/03/2025 | E52: 07/04/2025 | F52: POoja Shah | G52: Female | H52: 20/02/1979 | I52: Bengaluru | J52: South | K52: Home Appliances | L52: Iron | M52: 7 | N52: 2200 | O52: 15 | P52: 13090 | Q52: 1 | R52: UPI | S52: Aisha | T52: pooja.shah@company.com | U52: 9485166307 | V52: Completed | W52: =IF(OR(Q52<=2, V52="Cancelled"), "Blacklisted", IF(AND(P52>=100000, Q52>=4, O52<=10, V52="Completed"), "Platinum", IF(AND(P52>=50000, P52<=99999, Q52>=3, V52="Completed"), "Gold", IF(AND(P52<50000, V52="Completed"), "Silver", "Pending")))) -> Blacklisted
A53: ORD10052 | B53: C002 | C53: P301 | D53: 25/08/2025 | E53: 28/08/2025 | F53: Priya Patel | G53: Female | H53: 09/08/2000 | I53: Jaipur | J53: North | K53: Stationery | L53: Notebook | M53: 8 | N53: 60 | O53: 10 | P53: 432 | Q53: 5 | R53: Card | S53: Aisha | T53: priya.patel@company.com | U53: 9924709648 | V53: Cancelled | W53: =IF(OR(Q53<=2, V53="Cancelled"), "Blacklisted", IF(AND(P53>=100000, Q53>=4, O53<=10, V53="Completed"), "Platinum", IF(AND(P53>=50000, P53<=99999, Q53>=3, V53="Completed"), "Gold", IF(AND(P53<50000, V53="Completed"), "Silver", "Pending")))) -> Blacklisted
A54: ORD10053 | B54: C005 | C54: P101 | D54: 19/08/2025 | E54: 23/08/2025 | F54: Vikas Mehta | G54: Male | H54: 17/01/1976 | I54: Kolkata | J54: East | K54: Electronics | L54: Laptop | M54: 12 | N54: 55000 | O54: 5 | P54: 627000 | Q54: 2 | R54: UPI | S54: Rahul | T54: vikas.mehta@company.com | U54: 9350554626 | V54: Pending | W54: =IF(OR(Q54<=2, V54="Cancelled"), "Blacklisted", IF(AND(P54>=100000, Q54>=4, O54<=10, V54="Completed"), "Platinum", IF(AND(P54>=50000, P54<=99999, Q54>=3, V54="Completed"), "Gold", IF(AND(P54<50000, V54="Completed"), "Silver", "Pending")))) -> Blacklisted
A55: ORD10054 | B55: C008 | C55: P102 | D55: 27/07/2025 | E55: 05/08/2025 | F55: Kavya Nair | G55: Female | H55: 04/04/1975 | I55: Jaipur | J55: North | K55: Electronics | L55: Mouse | M55: 3 | N55: 700 | O55: 0 | P55: 2100 | Q55: 3 | R55: Card | S55: Karan | T55: kavya.nair@company.com | U55: 9743295580 | V55: Cancelled | W55: =IF(OR(Q55<=2, V55="Cancelled"), "Blacklisted", IF(AND(P55>=100000, Q55>=4, O55<=10, V55="Completed"), "Platinum", IF(AND(P55>=50000, P55<=99999, Q55>=3, V55="Completed"), "Gold", IF(AND(P55<50000, V55="Completed"), "Silver", "Pending")))) -> Blacklisted
A56: ORD10055 | B56: C003 | C56: P301 | D56: 21/02/2025 | E56: 26/02/2025 | F56: RoHit Singh | G56: Male | H56: 11/12/1976 | I56: Ahmedabad | J56: West | K56: Stationery | L56: Notebook | M56: 19 | N56: 60 | O56: 15 | P56: 969 | Q56: 4 | R56: Card | S56: Rahul | T56: rohit.singh@company.com | U56: 9822926495 | V56: Cancelled | W56: =IF(OR(Q56<=2, V56="Cancelled"), "Blacklisted", IF(AND(P56>=100000, Q56>=4, O56<=10, V56="Completed"), "Platinum", IF(AND(P56>=50000, P56<=99999, Q56>=3, V56="Completed"), "Gold", IF(AND(P56<50000, V56="Completed"), "Silver", "Pending")))) -> Blacklisted
A57: ORD10056 | B57: C001 | C57: P301 | D57: 10/08/2025 | E57: 11/08/2025 | F57: Amit Sharma | G57: Male | H57: 03/12/1979 | I57: Jaipur | J57: North | K57: Stationery | L57: Notebook | M57: 9 | N57: 60 | O57: 20 | P57: 432 | Q57: 1 | R57: NetBanking | S57: Neha | T57: amit.sharma@company.com | U57: 9518298190 | V57: Pending | W57: =IF(OR(Q57<=2, V57="Cancelled"), "Blacklisted", IF(AND(P57>=100000, Q57>=4, O57<=10, V57="Completed"), "Platinum", IF(AND(P57>=50000, P57<=99999, Q57>=3, V57="Completed"), "Gold", IF(AND(P57<50000, V57="Completed"), "Silver", "Pending")))) -> Blacklisted
A58: ORD10057 | B58: C001 | C58: P102 | D58: 24/03/2026 | E58: 30/03/2026 | F58: Amit Sharma | G58: Male | H58: 27/12/1978 | I58: Bengaluru | J58: South | K58: Electronics | L58: Mouse | M58: 6 | N58: 700 | O58: 0 | P58: 4200 | Q58: 4 | R58: UPI | S58: Rahul | T58: amit.sharmcompany.com | U58: 9366223547 | V58: Cancelled | W58: =IF(OR(Q58<=2, V58="Cancelled"), "Blacklisted", IF(AND(P58>=100000, Q58>=4, O58<=10, V58="Completed"), "Platinum", IF(AND(P58>=50000, P58<=99999, Q58>=3, V58="Completed"), "Gold", IF(AND(P58<50000, V58="Completed"), "Silver", "Pending")))) -> Blacklisted
A59: ORD10058 | B59: C003 | C59: P303 | D59: 13/03/2026 | E59: 19/03/2026 | F59: Rohit Singh | G59: Male | H59: 15/04/1975 | I59: Delhi | J59: North | K59: Stationery | L59: Marker | M59: 18 | N59: 45 | O59: 5 | P59: 769.5 | Q59: 1 | R59: Card | S59: Aisha | T59: rohit.singh@company.com | U59: 9701988524 | V59: Pending | W59: =IF(OR(Q59<=2, V59="Cancelled"), "Blacklisted", IF(AND(P59>=100000, Q59>=4, O59<=10, V59="Completed"), "Platinum", IF(AND(P59>=50000, P59<=99999, Q59>=3, V59="Completed"), "Gold", IF(AND(P59<50000, V59="Completed"), "Silver", "Pending")))) -> Blacklisted
A60: ORD10059 | B60: C007 | C60: P302 | D60: 15/06/2025 | E60: 26/06/2025 | F60: Arjun Rao | G60: Male | H60: 19/12/1988 | I60: Jaipur | J60: North | K60: Stationery | L60: Pen | M60: 8 | N60: 20 | O60: 5 | P60: 152 | Q60: 1 | R60: Card | S60: Ritika | T60: arjun.rao@company.com | U60: 9836327649 | V60: completed | W60: =IF(OR(Q60<=2, V60="Cancelled"), "Blacklisted", IF(AND(P60>=100000, Q60>=4, O60<=10, V60="Completed"), "Platinum", IF(AND(P60>=50000, P60<=99999, Q60>=3, V60="Completed"), "Gold", IF(AND(P60<50000, V60="Completed"), "Silver", "Pending")))) -> Blacklisted
A61: ORD10060 | B61: C005 | C61: P102 | D61: 05/03/2025 | E61: 06/03/2025 | F61: Vikas Mehta | G61: Male | H61: 07/03/1979 | I61: Jaipur | J61: North | K61: Electronics | L61: Mouse | M61: 8 | N61: 700 | O61: 10 | P61: 5040 | Q61: 1 | R61: NetBanking | S61: Aisha | T61: Vikas.mehta@company.com | U61: 9261800516 | V61: Cancelled | W61: =IF(OR(Q61<=2, V61="Cancelled"), "Blacklisted", IF(AND(P61>=100000, Q61>=4, O61<=10, V61="Completed"), "Platinum", IF(AND(P61>=50000, P61<=99999, Q61>=3, V61="Completed"), "Gold", IF(AND(P61<50000, V61="Completed"), "Silver", "Pending")))) -> Blacklisted
A62: ORD10061 | B62: C008 | C62: P302 | D62: 09/04/2026 | E62: 19/04/2026 | F62: Kavya Nair | G62: Female | H62: 17/12/2003 | I62: Delhi | J62: North | K62: Stationery | L62: Pen | M62: 7 | N62: 20 | O62: 15 | P62: 119 | Q62: 5 | R62: Card | S62: Rahul | T62: kavya.nair@company.com | U62: 9950802015 | V62: Completed | W62: =IF(OR(Q62<=2, V62="Cancelled"), "Blacklisted", IF(AND(P62>=100000, Q62>=4, O62<=10, V62="Completed"), "Platinum", IF(AND(P62>=50000, P62<=99999, Q62>=3, V62="Completed"), "Gold", IF(AND(P62<50000, V62="Completed"), "Silver", "Pending")))) -> Silver
... A74: ORD10073 | B74: C008 | C74: P103 | D74: 13/12/2025 | E74: 23/12/2025 | F74: Kavya Nair | G74: Female | H74: 22/09/1981 | I74: Jaipur | J74: North | K74: Electronics | L74: Keyboard | M74: 1 | N74: 1200 | O74: 5 | P74: 1140 | Q74: 3 | R74: UPI | S74: Aisha | T74: kavya.nair@company.com | U74: 9808988530 | V74: Cancelled | W74: =IF(OR(Q74<=2, V74="Cancelled"), "Blacklisted", IF(AND(P74>=100000, Q74>=4, O74<=10, V74="Completed"), "Platinum", IF(AND(P74>=50000, P74<=99999, Q74>=3, V74="Completed"), "Gold", IF(AND(P74<50000, V74="Completed"), "Silver", "Pending")))) -> Blacklisted
A75: ORD10074 | B75: C010 | C75: P202 | D75: 04/02/2026 | E75: 16/02/2026 | F75: Pooja Shah | G75: Female | H75: 20/06/1980 | J75: South | K75: Home Appliances | L75: Iron | M75: 1 | N75: 2200 | O75: 15 | P75: 1870 | Q75: 4 | R75: Card | S75: Aisha | T75: pooja.shah@company.com | U75: 9286410494 | V75: Completed | W75: =IF(OR(Q75<=2, V75="Cancelled"), "Blacklisted", IF(AND(P75>=100000, Q75>=4, O75<=10, V75="Completed"), "Platinum", IF(AND(P75>=50000, P75<=99999, Q75>=3, V75="Completed"), "Gold", IF(AND(P75<50000, V75="Completed"), "Silver", "Pending")))) -> Silver
A76: ORD10075 | B76: C003 | C76: P103 | D76: 26/01/2026 | E76: 28/01/2026 | F76: Rohit Singh | G76: Male | H76: 02/11/1982 | I76: Pune | J76: West | K76: Electronics | L76: Keyboard | M76: 3 | N76: 1200 | O76: 10 | P76: 3240 | Q76: 5 | R76: Cash | S76: Rahul | T76: rohit.singh@company.com | U76: 9311555196 | V76: Completed | W76: =IF(OR(Q76<=2, V76="Cancelled"), "Blacklisted", IF(AND(P76>=100000, Q76>=4, O76<=10, V76="Completed"), "Platinum", IF(AND(P76>=50000, P76<=99999, Q76>=3, V76="Completed"), "Gold", IF(AND(P76<50000, V76="Completed"), "Silver", "Pending")))) -> Silver
...

Sheet Q2
A1: Customer_Name | B1: Customer Code | C1: Email
A2: =TRIM(PROPER(Sales_Data!F2)) -> Kavya Nair | B2: =_xlfn.CONCAT(LEFT(A2,3),RIGHT(Sales_Data!B2,3),LEFT(Sales_Data!I2,2)) -> Kav008Hy | C2: =IF(COUNTIF(Sales_Data!T2, "*@*"), LOWER(TRIM(Sales_Data!T2)), "Invalid Email") -> kavya.nair@company.com
A3: =TRIM(PROPER(Sales_Data!F3)) -> Kavya Nair | B3: =_xlfn.CONCAT(LEFT(A3,3),RIGHT(Sales_Data!B3,3),LEFT(Sales_Data!I3,2)) -> Kav008De | C3: =IF(COUNTIF(Sales_Data!T3, "*@*"), LOWER(TRIM(Sales_Data!T3)), "Invalid Email") -> kavya.nair@company.com
A4: =TRIM(PROPER(Sales_Data!F4)) -> Pooja Shah | B4: =_xlfn.CONCAT(LEFT(A4,3),RIGHT(Sales_Data!B4,3),LEFT(Sales_Data!I4,2)) -> Poo010Be | C4: =IF(COUNTIF(Sales_Data!T4, "*@*"), LOWER(TRIM(Sales_Data!T4)), "Invalid Email") -> pooja.shah@company.com
A5: =TRIM(PROPER(Sales_Data!F5)) -> Kavya Nair | B5: =_xlfn.CONCAT(LEFT(A5,3),RIGHT(Sales_Data!B5,3),LEFT(Sales_Data!I5,2)) -> Kav008Be | C5: =IF(COUNTIF(Sales_Data!T5, "*@*"), LOWER(TRIM(Sales_Data!T5)), "Invalid Email") -> kavya.nair@company.com
A6: =TRIM(PROPER(Sales_Data!F6)) -> Mohit Verma | B6: =_xlfn.CONCAT(LEFT(A6,3),RIGHT(Sales_Data!B6,3),LEFT(Sales_Data!I6,2)) -> Moh009De | C6: =IF(COUNTIF(Sales_Data!T6, "*@*"), LOWER(TRIM(Sales_Data!T6)), "Invalid Email") -> mohit.verma@company.com
A7: =TRIM(PROPER(Sales_Data!F7)) -> Arjun Rao | B7: =_xlfn.CONCAT(LEFT(A7,3),RIGHT(Sales_Data!B7,3),LEFT(Sales_Data!I7,2)) -> Arj007Hy | C7: =IF(COUNTIF(Sales_Data!T7, "*@*"), LOWER(TRIM(Sales_Data!T7)), "Invalid Email") -> arjun.rao@company.com
A8: =TRIM(PROPER(Sales_Data!F8)) -> Kavya Nair | B8: =_xlfn.CONCAT(LEFT(A8,3),RIGHT(Sales_Data!B8,3),LEFT(Sales_Data!I8,2)) -> Kav008Hy | C8: =IF(COUNTIF(Sales_Data!T8, "*@*"), LOWER(TRIM(Sales_Data!T8)), "Invalid Email") -> kavya.nair@company.com
A9: =TRIM(PROPER(Sales_Data!F9)) -> Priya Patel | B9: =_xlfn.CONCAT(LEFT(A9,3),RIGHT(Sales_Data!B9,3),LEFT(Sales_Data!I9,2)) -> Pri002Mu | C9: =IF(COUNTIF(Sales_Data!T9, "*@*"), LOWER(TRIM(Sales_Data!T9)), "Invalid Email") -> priya.patel@company.com
A10: =TRIM(PROPER(Sales_Data!F10)) -> Kavya Nair | B10: =_xlfn.CONCAT(LEFT(A10,3),RIGHT(Sales_Data!B10,3),LEFT(Sales_Data!I10,2)) -> Kav008Pu | C10: =IF(COUNTIF(Sales_Data!T10, "*@*"), LOWER(TRIM(Sales_Data!T10)), "Invalid Email") -> kavya.nair@company.com
A11: =TRIM(PROPER(Sales_Data!F11)) -> Priya Patel | B11: =_xlfn.CONCAT(LEFT(A11,3),RIGHT(Sales_Data!B11,3),LEFT(Sales_Data!I11,2)) -> Pri002Mu | C11: =IF(COUNTIF(Sales_Data!T11, "*@*"), LOWER(TRIM(Sales_Data!T11)), "Invalid Email") -> priya.patel@company.com
A12: =TRIM(PROPER(Sales_Data!F12)) -> Rohit Singh | B12: =_xlfn.CONCAT(LEFT(A12,3),RIGHT(Sales_Data!B12,3),LEFT(Sales_Data!I12,2)) -> Roh003De | C12: =IF(COUNTIF(Sales_Data!T12, "*@*"), LOWER(TRIM(Sales_Data!T12)), "Invalid Email") -> rohit.singh@company.com
A13: =TRIM(PROPER(Sales_Data!F13)) -> Kavya Nair | B13: =_xlfn.CONCAT(LEFT(A13,3),RIGHT(Sales_Data!B13,3),LEFT(Sales_Data!I13,2)) -> Kav008Ah | C13: =IF(COUNTIF(Sales_Data!T13, "*@*"), LOWER(TRIM(Sales_Data!T13)), "Invalid Email") -> kavya.nair@company.com
... A502: =TRIM(PROPER(Sales_Data!F502)) | B502: =_xlfn.CONCAT(LEFT(A502,3),RIGHT(Sales_Data!B502,3),LEFT(Sales_Data!I502,2)) | C502: =IF(COUNTIF(Sales_Data!T502, "*@*"), LOWER(TRIM(Sales_Data!T502)), "Invalid Email") -> Invalid Email

Sheet Q3
A1: Order_ID | B1: Customer_ID | C1: Product_ID | D1: Order_Date | E1: Delivery_Date | F1: Customer_Name | G1: Gender | H1: DOB | I1: City | J1: Region | K1: Category | L1: Product_Name | M1: Quantity | N1: Unit_Price | O1: Discount_% | P1: Sales | Q1: Rating | R1: Payment_Mode | S1: Salesperson | T1: Email | U1: Phone | V1: Order_Status | W1: Customer Age | X1: Delivery time (Days) | Y1: Delivery Status
A2: ORD10001 | B2: C008 | C2: P202 | D2: 45918 | E2: 45922 | F2: Kavya Nair | G2: Female | H2: 27767 | I2: Hyderabad | J2: South | K2: Home Appliances | L2: Iron | M2: 4 | N2: 2200 | O2: 10 | P2: 7920 | Q2: 4 | R2: Cash | S2: Ritika | T2: KAvya.nair@company.com | U2: 9431429797 | V2: Completed | W2: =DATEDIF(H2,TODAY(),"Y") -> 50 | X2: =DATEDIF(D2,E2,"D") -> 4 | Y2: {=_xlfn.IFS(ISERROR(X2), "Pending", X2<=5, "On Time", X2>5, "Delayed")} -> On Time
A3: ORD10002 | B3: C008 | C3: P104 | D3: 45774 | E3: 45781 | F3: Kavya Nair | G3: Female | H3: 36815 | I3: Delhi | J3: North | K3: Electronics | L3: Monitor | M3: 17 | N3: 12000 | O3: 10 | P3: 183600 | Q3: 1 | R3: NetBanking | S3: Rahul | T3: kavya.nair@company.com | U3: 9129865339 | V3: Completed | W3: =DATEDIF(H3,TODAY(),"Y") -> 25 | X3: =DATEDIF(D3,E3,"D") -> 7 | Y3: {=_xlfn.IFS(ISERROR(X3), "Pending", X3<=5, "On Time", X3>5, "Delayed")} -> Delayed
A4: ORD10003 | B4: C010 | C4: P101 | D4: 45903 | E4: 45914 | F4: pooja shah | G4: Female | H4: 34593 | I4: Bengaluru | J4: South | K4: Electronics | L4: Laptop | M4: 5 | N4: 55000 | O4: 5 | P4: 261250 | Q4: 3 | R4: NetBanking | S4: Aisha | T4: pooja.shah@company.com | U4: 9380975626 | V4: Pending | W4: =DATEDIF(H4,TODAY(),"Y") -> 31 | X4: =DATEDIF(D4,E4,"D") -> 11 | Y4: {=_xlfn.IFS(ISERROR(X4), "Pending", X4<=5, "On Time", X4>5, "Delayed")} -> Delayed
A5: ORD10002 | B5: C008 | C5: P202 | D5: 46102 | E5: 46114 | F5: Kavya Nair | G5: Female | H5: 38171 | I5: Bengaluru | J5: South | K5: Home Appliances | L5: Iron | M5: 5 | N5: 2200 | O5: 5 | P5: 10450 | Q5: 5 | R5: NetBanking | S5: Aisha | T5: kavya.nair@company.com | U5: 9600261125 | V5: Cancelled | W5: =DATEDIF(H5,TODAY(),"Y") -> 22 | X5: =DATEDIF(D5,E5,"D") -> 12 | Y5: {=_xlfn.IFS(ISERROR(X5), "Pending", X5<=5, "On Time", X5>5, "Delayed")} -> Delayed
A6: ORD10005 | B6: C009 | C6: P103 | D6: 45927 | E6: 45937 | F6: Mohit Verma | G6: Male | H6: 27863 | I6: Delhi | J6: North | K6: Electronics | L6: Keyboard | M6: 8 | N6: 1200 | O6: 5 | P6: 9120 | Q6: 2 | R6: Card | S6: Aisha | T6: mohit.verma@company.com | U6: 9724635978 | V6: Pending | W6: =DATEDIF(H6,TODAY(),"Y") -> 50 | X6: =DATEDIF(D6,E6,"D") -> 10 | Y6: {=_xlfn.IFS(ISERROR(X6), "Pending", X6<=5, "On Time", X6>5, "Delayed")} -> Delayed
A7: ORD10006 | B7: C007 | C7: P202 | D7: 46026 | E7: 46034 | F7: arjun Rao | G7: Male | H7: 32326 | I7: Hyderabad | J7: South | K7: Home Appliances | L7: Iron | M7: 4 | N7: 2200 | O7: 0 | P7: 8800 | Q7: 1 | R7: UPI | S7: Ritika | T7: arjun.rao@company.com | U7: 9780584905 | V7: Completed | W7: =DATEDIF(H7,TODAY(),"Y") -> 38 | X7: =DATEDIF(D7,E7,"D") -> 8 | Y7: {=_xlfn.IFS(ISERROR(X7), "Pending", X7<=5, "On Time", X7>5, "Delayed")} -> Delayed
A8: ORD10007 | B8: C008 | C8: P201 | D8: 31/02/2025 | E8: 46078 | F8: Kavya Nair | G8: Female | H8: 37700 | I8: Hyderabad | J8: South | K8: Home Appliances | L8: Mixer | M8: 2 | N8: 3500 | O8: 5 | P8: 6650 | Q8: 1 | R8: UPI | S8: Ritika | T8: kavya.nair@company.com | U8: 9958252176 | V8: Completed | W8: =DATEDIF(H8,TODAY(),"Y") -> 23 | X8: =DATEDIF(D8,E8,"D") -> #VALUE! | Y8: {=_xlfn.IFS(ISERROR(X8), "Pending", X8<=5, "On Time", X8>5, "Delayed")} -> Pending
A9: ORD10008 | B9: C002 | C9: P104 | D9: 45760 | E9: 45766 | F9: Priya Patel | G9: Female | H9: 34883 | I9: Mumbai | J9: West | K9: Electronics | L9: Monitor | M9: 14 | N9: 12000 | O9: 15 | P9: 142800 | Q9: 4 | R9: NetBanking | S9: Ritika | T9: priYa.patel@company.com | U9: 9705521654 | V9: Completed | W9: =DATEDIF(H9,TODAY(),"Y") -> 31 | X9: =DATEDIF(D9,E9,"D") -> 6 | Y9: {=_xlfn.IFS(ISERROR(X9), "Pending", X9<=5, "On Time", X9>5, "Delayed")} -> Delayed
A10: ORD10009 | B10: C008 | C10: P104 | D10: 46053 | E10: 46055 | F10: kavya Nair | G10: Female | H10: 35585 | I10: Pune | J10: West | K10: Electronics | L10: Monitor | M10: 4 | N10: 12000 | O10: 15 | P10: 40800 | Q10: 4 | R10: UPI | S10: Neha | T10: kavya.nair@company.com | U10: 9588041011 | V10: Completed | W10: =DATEDIF(H10,TODAY(),"Y") -> 29 | X10: =DATEDIF(D10,E10,"D") -> 2 | Y10: {=_xlfn.IFS(ISERROR(X10), "Pending", X10<=5, "On Time", X10>5, "Delayed")} -> On Time
A11: ORD10010 | B11: C002 | C11: P301 | D11: 45741 | E11: 45743 | F11: Priya Patel | G11: Female | H11: 33055 | I11: Mumbai | J11: West | K11: Stationery | L11: Notebook | M11: 6 | N11: 60 | O11: 0 | P11: 360 | Q11: 4 | R11: Card | S11: Neha | T11: PRiya.patel@company.com | U11: 9340540608 | V11: Completed | W11: =DATEDIF(H11,TODAY(),"Y") -> 36 | X11: =DATEDIF(D11,E11,"D") -> 2 | Y11: {=_xlfn.IFS(ISERROR(X11), "Pending", X11<=5, "On Time", X11>5, "Delayed")} -> On Time
A12: ORD10011 | B12: C003 | C12: P202 | D12: 45919 | E12: 45923 | F12: Rohit Singh | G12: Male | H12: 30229 | I12: Delhi | J12: North | K12: Home Appliances | L12: Iron | M12: -3 | N12: 2200 | O12: 0 | P12: 35200 | Q12: 2 | R12: Card | S12: Rahul | T12: rohit.singh@company.com | U12: 9521710321 | V12: Pending | W12: =DATEDIF(H12,TODAY(),"Y") -> 43 | X12: =DATEDIF(D12,E12,"D") -> 4 | Y12: {=_xlfn.IFS(ISERROR(X12), "Pending", X12<=5, "On Time", X12>5, "Delayed")} -> On Time
A13: ORD10012 | B13: C008 | C13: P201 | D13: 45724 | E13: 45731 | F13: Kavya Nair | G13: Female | H13: 29974 | I13: Ahmedabad | J13: West | K13: Home Appliances | L13: Mixer | M13: 10 | N13: 3500 | O13: 5 | P13: 33250 | Q13: 5 | R13: Card | S13: Aisha | T13: kavya.nair@company.com | U13: 9123535241 | V13: Cancelled | W13: =DATEDIF(H13,TODAY(),"Y") -> 44 | X13: =DATEDIF(D13,E13,"D") -> 7 | Y13: {=_xlfn.IFS(ISERROR(X13), "Pending", X13<=5, "On Time", X13>5, "Delayed")} -> Delayed
A14: ORD10013 | B14: C002 | C14: P202 | D14: 45667 | E14: 45672 | F14: Priya Patel | G14: Female | H14: 33762 | I14: Pune | J14: West | K14: Home Appliances | L14: Iron | M14: 15 | N14: 2200 | O14: 10 | P14: 29700 | Q14: 1 | R14: UPI | S14: Neha | T14: priya.patel@company.com | U14: 9367316892 | V14: Pending | W14: =DATEDIF(H14,TODAY(),"Y") -> 34 | X14: =DATEDIF(D14,E14,"D") -> 5 | Y14: {=_xlfn.IFS(ISERROR(X14), "Pending", X14<=5, "On Time", X14>5, "Delayed")} -> On Time
A15: ORD10014 | B15: C003 | C15: P202 | D15: 45725 | E15: 45729 | F15: rohit Singh | G15: Male | H15: 37334 | I15: Mumbai | J15: West | K15: Home Appliances | L15: Iron | M15: 17 | N15: 2200 | O15: 5 | P15: 35530 | Q15: 1 | R15: Cash | S15: Karan | T15: rOhit.singh@company.com | U15: 9778489803 | V15: Completed | W15: =DATEDIF(H15,TODAY(),"Y") -> 24 | X15: =DATEDIF(D15,E15,"D") -> 4 | Y15: {=_xlfn.IFS(ISERROR(X15), "Pending", X15<=5, "On Time", X15>5, "Delayed")} -> On Time
A16: ORD10015 | B16: C008 | C16: P201 | D16: 45864 | E16: 45876 | F16: Kavya nair | G16: Female | H16: 36908 | I16: Mumbai | J16: West | K16: Home Appliances | L16: Mixer | M16: 15 | N16: 3500 | O16: 15 | P16: 44625 | Q16: 2 | R16: Cash | S16: Neha | T16: kavya.nair@company.com | U16: 9582960180 | V16: Cancelled | W16: =DATEDIF(H16,TODAY(),"Y") -> 25 | X16: =DATEDIF(D16,E16,"D") -> 12 | Y16: {=_xlfn.IFS(ISERROR(X16), "Pending", X16<=5, "On Time", X16>5, "Delayed")} -> Delayed
A17: ORD10016 | B17: C010 | C17: P103 | D17: 46120 | E17: 46123 | F17: Pooja Shah | G17: Female | H17: 37564 | I17: Hyderabad | J17: South | K17: Electronics | L17: Keyboard | M17: 3 | N17: 1200 | O17: 5 | P17: 3420 | Q17: 5 | R17: UPI | S17: Ritika | T17: pooja.shahcompany.com | U17: 9611394005 | V17: Completed | W17: =DATEDIF(H17,TODAY(),"Y") -> 23 | X17: =DATEDIF(D17,E17,"D") -> 3 | Y17: {=_xlfn.IFS(ISERROR(X17), "Pending", X17<=5, "On Time", X17>5, "Delayed")} -> On Time
A18: ORD10017 | B18: C004 | C18: P203 | D18: 46075 | E18: 46084 | F18: Amit Sharma | G18: Female | H18: 37272 | I18: Pune | J18: West | K18: Home Appliances | L18: Microwave | M18: 13 | N18: 8500 | O18: 20 | P18: 88400 | Q18: 4 | R18: Card | S18: Rahul | T18: anita.gupta@company.com | U18: 9692599404 | V18: Pending | W18: =DATEDIF(H18,TODAY(),"Y") -> 24 | X18: =DATEDIF(D18,E18,"D") -> 9 | Y18: {=_xlfn.IFS(ISERROR(X18), "Pending", X18<=5, "On Time", X18>5, "Delayed")} -> Delayed
A19: ORD10018 | B19: C007 | C19: P203 | D19: 46081 | E19: 46086 | F19: Arjun Rao | G19: Male | H19: 32761 | I19: Ahmedabad | J19: West | K19: Home Appliances | L19: Microwave | M19: 4 | N19: 8500 | O19: 20 | P19: 27200 | Q19: 5 | R19: Card | S19: Aisha | T19: arjun.rao@company.com | U19: 9426119622 | V19: Pending | W19: =DATEDIF(H19,TODAY(),"Y") -> 36 | X19: =DATEDIF(D19,E19,"D") -> 5 | Y19: {=_xlfn.IFS(ISERROR(X19), "Pending", X19<=5, "On Time", X19>5, "Delayed")} -> On Time
A20: ORD10019 | B20: C007 | C20: P102 | D20: 45992 | E20: 45995 | F20: arjun rao | G20: Male | H20: 33539 | I20: Mumbai | J20: West | K20: Electronics | L20: Mouse | M20: 9 | N20: 700 | O20: 5 | P20: 5985 | Q20: 3 | R20: UPI | S20: Ritika | T20: arjun.Rao@company.com | U20: 9184436009 | V20: Pending | W20: =DATEDIF(H20,TODAY(),"Y") -> 34 | X20: =DATEDIF(D20,E20,"D") -> 3 | Y20: {=_xlfn.IFS(ISERROR(X20), "Pending", X20<=5, "On Time", X20>5, "Delayed")} -> On Time
... A39: ORD10038 | B39: C006 | C39: P201 | D39: 46089 | E39: 46101 | F39: Sneha Joshi | G39: Female | H39: 29393 | I39: Delhi | J39: North | K39: Home Appliances | L39: Mixer | M39: 20 | N39: 3500 | O39: 10 | P39: 63000 | Q39: 3 | R39: Card | S39: Rahul | T39: sneha.joshi@company.com | U39: 9283578533 | V39: Cancelled | W39: =DATEDIF(H39,TODAY(),"Y") -> 46 | X39: =DATEDIF(D39,E39,"D") -> 12 | Y39: {=_xlfn.IFS(ISERROR(X39), "Pending", X39<=5, "On Time", X39>5, "Delayed")} -> Delayed
A40: ORD10039 | B40: C008 | C40: P302 | D40: 45701 | E40: 45707 | F40: Kavya Nair | G40: Female | H40: 29023 | I40: Pune | J40: West | K40: Stationery | L40: Pen | M40: 5 | N40: 1200 | O40: 0 | P40: 100 | Q40: 1 | R40: Cash | S40: Rahul | T40: kavya.nair@company.com | U40: 9963005771 | V40: Cancelled | W40: =DATEDIF(H40,TODAY(),"Y") -> 47 | X40: =DATEDIF(D40,E40,"D") -> 6 | Y40: {=_xlfn.IFS(ISERROR(X40), "Pending", X40<=5, "On Time", X40>5, "Delayed")} -> Delayed
A41: ORD10040 | B41: C010 | C41: P203 | D41: 45935 | E41: 45945 | F41: Pooja Shah | G41: Female | H41: 33773 | I41: Mumbai | J41: West | K41: Home Appliances | L41: Microwave | M41: 20 | N41: 8500 | O41: 0 | P41: 170000 | Q41: 1 | R41: UPI | S41: Neha | T41: pooja.shah@company.com | U41: 9484632635 | V41: Cancelled | W41: =DATEDIF(H41,TODAY(),"Y") -> 34 | X41: =DATEDIF(D41,E41,"D") -> 10 | Y41: {=_xlfn.IFS(ISERROR(X41), "Pending", X41<=5, "On Time", X41>5, "Delayed")} -> Delayed
A42: ORD10041 | B42: C007 | C42: P301 | D42: 46063 | E42: 46065 | F42: Arjun Rao | G42: Male | H42: 34491 | I42: Bengaluru | J42: South | K42: Stationery | L42: Notebook | M42: 8 | N42: 60 | O42: 15 | P42: 408 | Q42: 5 | R42: UPI | S42: Rahul | T42: arjun.rao@company.com | U42: 9276319484 | V42: Pending | W42: =DATEDIF(H42,TODAY(),"Y") -> 32 | X42: =DATEDIF(D42,E42,"D") -> 2 | Y42: {=_xlfn.IFS(ISERROR(X42), "Pending", X42<=5, "On Time", X42>5, "Delayed")} -> On Time
A43: ORD10042 | B43: C010 | C43: P201 | D43: 45812 | E43: 45824 | F43: Pooja Shah | G43: Female | H43: 32408 | I43: Pune | J43: West | K43: Home Appliances | L43: Mixer | M43: 8 | N43: 3500 | O43: 5 | P43: 26600 | Q43: 1 | R43: Card | S43: Neha | T43: pooja.shah@company.com | U43: 9619034852 | V43: Pending | W43: =DATEDIF(H43,TODAY(),"Y") -> 37 | X43: =DATEDIF(D43,E43,"D") -> 12 | Y43: {=_xlfn.IFS(ISERROR(X43), "Pending", X43<=5, "On Time", X43>5, "Delayed")} -> Delayed
A44: ORD10043 | B44: C009 | C44: P203 | D44: 46061 | E44: 46067 | F44: Mohit Verma | G44: Male | H44: 37086 | I44: Jaipur | J44: North | K44: Home Appliances | L44: Microwave | M44: 1 | N44: 8500 | O44: 0 | P44: 8500 | Q44: 2 | R44: Card | S44: Neha | T44: mohit.verma@company.com | U44: 9636416962 | V44: Pending | W44: =DATEDIF(H44,TODAY(),"Y") -> 25 | X44: =DATEDIF(D44,E44,"D") -> 6 | Y44: {=_xlfn.IFS(ISERROR(X44), "Pending", X44<=5, "On Time", X44>5, "Delayed")} -> Delayed
A45: ORD10044 | B45: C001 | C45: P303 | D45: 45746 | E45: 45747 | F45: amit Sharma | G45: Male | H45: 33489 | I45: Pune | J45: West | K45: Stationery | L45: Marker | M45: 8 | N45: 45 | O45: 15 | P45: 306 | Q45: 2 | R45: Card | S45: Aisha | T45: amit.sharma@company.com | U45: 9357133880 | V45: Completed | W45: =DATEDIF(H45,TODAY(),"Y") -> 34 | X45: =DATEDIF(D45,E45,"D") -> 1 | Y45: {=_xlfn.IFS(ISERROR(X45), "Pending", X45<=5, "On Time", X45>5, "Delayed")} -> On Time
A46: ORD10045 | B46: C006 | C46: P202 | D46: 45772 | E46: 45775 | F46: Sneha Joshi | G46: Female | H46: 32437 | I46: Pune | J46: West | K46: Home Appliances | L46: Iron | M46: 16 | N46: 2200 | O46: 5 | P46: 33440 | Q46: 5 | R46: Card | S46: Aisha | T46: sneha.joshi@company.com | U46: 9575210324 | V46: Cancelled | W46: =DATEDIF(H46,TODAY(),"Y") -> 37 | X46: =DATEDIF(D46,E46,"D") -> 3 | Y46: {=_xlfn.IFS(ISERROR(X46), "Pending", X46<=5, "On Time", X46>5, "Delayed")} -> On Time
A47: ORD10046 | B47: C009 | C47: P201 | D47: 45943 | E47: 45953 | F47: Mohit Verma | G47: Male | H47: 37579 | I47: Bengaluru | J47: South | K47: Home Appliances | L47: Mixer | M47: 19 | N47: 3500 | O47: 20 | P47: 53200 | Q47: 3 | R47: Cash | S47: Karan | T47: mohit.verma@company.com | U47: 9276080204 | V47: Cancelled | W47: =DATEDIF(H47,TODAY(),"Y") -> 23 | X47: =DATEDIF(D47,E47,"D") -> 10 | Y47: {=_xlfn.IFS(ISERROR(X47), "Pending", X47<=5, "On Time", X47>5, "Delayed")} -> Delayed
A48: ORD10047 | B48: C006 | C48: P102 | D48: 45941 | E48: 45944 | F48: Sneha Joshi | G48: Female | H48: 36684 | I48: Pune | J48: West | K48: Electronics | L48: Mouse | M48: 15 | N48: 700 | O48: 15 | P48: 8925 | Q48: 4 | R48: UPI | S48: Neha | T48: sneha.joshicompany.com | U48: 9856624471 | V48: Completed | W48: =DATEDIF(H48,TODAY(),"Y") -> 26 | X48: =DATEDIF(D48,E48,"D") -> 3 | Y48: {=_xlfn.IFS(ISERROR(X48), "Pending", X48<=5, "On Time", X48>5, "Delayed")} -> On Time
A49: ORD10048 | B49: C006 | C49: P102 | D49: 45988 | E49: 45994 | F49: Sneha Joshi | G49: Female | H49: 36125 | I49: Jaipur | J49: North | K49: Electronics | L49: Mouse | M49: 19 | N49: 700 | O49: 20 | P49: 10640 | Q49: 1 | R49: Cash | S49: Neha | T49: sneha.joshi@company.com | U49: 9238141322 | V49: Completed | W49: =DATEDIF(H49,TODAY(),"Y") -> 27 | X49: =DATEDIF(D49,E49,"D") -> 6 | Y49: {=_xlfn.IFS(ISERROR(X49), "Pending", X49<=5, "On Time", X49>5, "Delayed")} -> Delayed
A50: ORD10049 | B50: C009 | C50: P104 | D50: 46131 | F50: Mohit Verma | G50: Male | H50: 35130 | I50: Delhi | J50: North | K50: Electronics | L50: Monitor | M50: 19 | N50: 12000 | O50: 0 | P50: 228000 | Q50: 1 | R50: NetBanking | S50: Aisha | T50: mohit.verma@company.com | U50: 9890380030 | V50: Completed | W50: =DATEDIF(H50,TODAY(),"Y") -> 30 | X50: =DATEDIF(D50,E50,"D") -> #NUM! | Y50: {=_xlfn.IFS(ISERROR(X50), "Pending", X50<=5, "On Time", X50>5, "Delayed")} -> Pending
A51: ORD10050 | B51: C004 | C51: P103 | D51: 46131 | E51: 46133 | F51: Anita Gupta | G51: Female | H51: 31851 | I51: Pune | J51: West | K51: Electronics | L51: Keyboard | M51: 6 | N51: 1200 | O51: 5 | P51: 6840 | Q51: 2 | R51: Cash | S51: Ritika | T51: anita.gupta@company.com | U51: 9495893170 | V51: Pending | W51: =DATEDIF(H51,TODAY(),"Y") -> 39 | X51: =DATEDIF(D51,E51,"D") -> 2 | Y51: {=_xlfn.IFS(ISERROR(X51), "Pending", X51<=5, "On Time", X51>5, "Delayed")} -> On Time
A52: ORD10051 | B52: C010 | C52: P202 | D52: 45744 | E52: 45754 | F52: POoja Shah | G52: Female | H52: 28906 | I52: Bengaluru | J52: South | K52: Home Appliances | L52: Iron | M52: 7 | N52: 2200 | O52: 15 | P52: 13090 | Q52: 1 | R52: UPI | S52: Aisha | T52: pooja.shah@company.com | U52: 9485166307 | V52: Completed | W52: =DATEDIF(H52,TODAY(),"Y") -> 47 | X52: =DATEDIF(D52,E52,"D") -> 10 | Y52: {=_xlfn.IFS(ISERROR(X52), "Pending", X52<=5, "On Time", X52>5, "Delayed")} -> Delayed
A53: ORD10052 | B53: C002 | C53: P301 | D53: 45894 | E53: 45897 | F53: Priya Patel | G53: Female | H53: 36777 | I53: Jaipur | J53: North | K53: Stationery | L53: Notebook | M53: 8 | N53: 60 | O53: 10 | P53: 432 | Q53: 5 | R53: Card | S53: Aisha | T53: priya.patel@company.com | U53: 9924709648 | V53: Cancelled | W53: =DATEDIF(H53,TODAY(),"Y") -> 25 | X53: =DATEDIF(D53,E53,"D") -> 3 | Y53: {=_xlfn.IFS(ISERROR(X53), "Pending", X53<=5, "On Time", X53>5, "Delayed")} -> On Time
A54: ORD10053 | B54: C005 | C54: P101 | D54: 45888 | E54: 45892 | F54: Vikas Mehta | G54: Male | H54: 27776 | I54: Kolkata | J54: East | K54: Electronics | L54: Laptop | M54: 12 | N54: 55000 | O54: 5 | P54: 627000 | Q54: 2 | R54: UPI | S54: Rahul | T54: vikas.mehta@company.com | U54: 9350554626 | V54: Pending | W54: =DATEDIF(H54,TODAY(),"Y") -> 50 | X54: =DATEDIF(D54,E54,"D") -> 4 | Y54: {=_xlfn.IFS(ISERROR(X54), "Pending", X54<=5, "On Time", X54>5, "Delayed")} -> On Time
A55: ORD10054 | B55: C008 | C55: P102 | D55: 45865 | E55: 45874 | F55: Kavya Nair | G55: Female | H55: 27488 | I55: Jaipur | J55: North | K55: Electronics | L55: Mouse | M55: 3 | N55: 700 | O55: 0 | P55: 2100 | Q55: 3 | R55: Card | S55: Karan | T55: kavya.nair@company.com | U55: 9743295580 | V55: Cancelled | W55: =DATEDIF(H55,TODAY(),"Y") -> 51 | X55: =DATEDIF(D55,E55,"D") -> 9 | Y55: {=_xlfn.IFS(ISERROR(X55), "Pending", X55<=5, "On Time", X55>5, "Delayed")} -> Delayed
A56: ORD10055 | B56: C003 | C56: P301 | D56: 45709 | E56: 45714 | F56: RoHit Singh | G56: Male | H56: 28076 | I56: Ahmedabad | J56: West | K56: Stationery | L56: Notebook | M56: 19 | N56: 60 | O56: 15 | P56: 969 | Q56: 4 | R56: Card | S56: Rahul | T56: rohit.singh@company.com | U56: 9822926495 | V56: Cancelled | W56: =DATEDIF(H56,TODAY(),"Y") -> 49 | X56: =DATEDIF(D56,E56,"D") -> 5 | Y56: {=_xlfn.IFS(ISERROR(X56), "Pending", X56<=5, "On Time", X56>5, "Delayed")} -> On Time
A57: ORD10056 | B57: C001 | C57: P301 | D57: 45879 | E57: 45880 | F57: Amit Sharma | G57: Male | H57: 28926 | I57: Jaipur | J57: North | K57: Stationery | L57: Notebook | M57: 9 | N57: 60 | O57: 20 | P57: 432 | Q57: 1 | R57: NetBanking | S57: Neha | T57: amit.sharma@company.com | U57: 9518298190 | V57: Pending | W57: =DATEDIF(H57,TODAY(),"Y") -> 47 | X57: =DATEDIF(D57,E57,"D") -> 1 | Y57: {=_xlfn.IFS(ISERROR(X57), "Pending", X57<=5, "On Time", X57>5, "Delayed")} -> On Time
A58: ORD10057 | B58: C001 | C58: P102 | D58: 46105 | E58: 46111 | F58: Amit Sharma | G58: Male | H58: 28851 | I58: Bengaluru | J58: South | K58: Electronics | L58: Mouse | M58: 6 | N58: 700 | O58: 0 | P58: 4200 | Q58: 4 | R58: UPI | S58: Rahul | T58: amit.sharmcompany.com | U58: 9366223547 | V58: Cancelled | W58: =DATEDIF(H58,TODAY(),"Y") -> 47 | X58: =DATEDIF(D58,E58,"D") -> 6 | Y58: {=_xlfn.IFS(ISERROR(X58), "Pending", X58<=5, "On Time", X58>5, "Delayed")} -> Delayed
...

Sheet Product Lookup Report (Q4)
B2: Product ID | C2: Product Name | D2: Supplier | E2: Cost Price | F2: Warrenty (Months)
